{"trial_id": "0", "hyperparameters": {"space": [{"class_name": "Int", "config": {"name": "n_hidden1", "default": null, "conditions": [], "min_value": 5, "max_value": 20, "step": 5, "sampling": "linear"}}, {"class_name": "Int", "config": {"name": "n_hidden2", "default": null, "conditions": [], "min_value": 5, "max_value": 20, "step": 5, "sampling": "linear"}}, {"class_name": "Float", "config": {"name": "learning_rate", "default": 0.001, "conditions": [], "min_value": 0.001, "max_value": 0.1, "step": 0.005, "sampling": "linear"}}], "values": {"n_hidden1": 15, "n_hidden2": 10, "learning_rate": 0.011}}, "metrics": {"metrics": {}}, "score": null, "best_step": 0, "status": "FAILED", "message": "Traceback (most recent call last):\n  File \"C:\\Users\\Juliu\\anaconda3\\lib\\site-packages\\keras_tuner\\engine\\base_tuner.py\", line 270, in _try_run_and_update_trial\n    self._run_and_update_trial(trial, *fit_args, **fit_kwargs)\n  File \"C:\\Users\\Juliu\\anaconda3\\lib\\site-packages\\keras_tuner\\engine\\base_tuner.py\", line 235, in _run_and_update_trial\n    results = self.run_trial(trial, *fit_args, **fit_kwargs)\n  File \"C:\\Users\\Juliu\\anaconda3\\lib\\site-packages\\keras_tuner\\engine\\tuner.py\", line 287, in run_trial\n    obj_value = self._build_and_fit_model(trial, *args, **copied_kwargs)\n  File \"C:\\Users\\Juliu\\anaconda3\\lib\\site-packages\\keras_tuner\\engine\\tuner.py\", line 214, in _build_and_fit_model\n    results = self.hypermodel.fit(hp, model, *args, **kwargs)\n  File \"C:\\Users\\Juliu\\anaconda3\\lib\\site-packages\\keras_tuner\\engine\\hypermodel.py\", line 144, in fit\n    return model.fit(*args, **kwargs)\n  File \"C:\\Users\\Juliu\\anaconda3\\lib\\site-packages\\keras\\utils\\traceback_utils.py\", line 70, in error_handler\n    raise e.with_traceback(filtered_tb) from None\n  File \"C:\\Users\\Juliu\\AppData\\Local\\Temp\\__autograph_generated_file7grpk_kk.py\", line 15, in tf__train_function\n    retval_ = ag__.converted_call(ag__.ld(step_function), (ag__.ld(self), ag__.ld(iterator)), None, fscope)\nValueError: in user code:\n\n    File \"C:\\Users\\Juliu\\anaconda3\\lib\\site-packages\\keras\\engine\\training.py\", line 1160, in train_function  *\n        return step_function(self, iterator)\n    File \"C:\\Users\\Juliu\\anaconda3\\lib\\site-packages\\keras\\engine\\training.py\", line 1146, in step_function  **\n        outputs = model.distribute_strategy.run(run_step, args=(data,))\n    File \"C:\\Users\\Juliu\\anaconda3\\lib\\site-packages\\keras\\engine\\training.py\", line 1135, in run_step  **\n        outputs = model.train_step(data)\n    File \"C:\\Users\\Juliu\\anaconda3\\lib\\site-packages\\keras\\engine\\training.py\", line 993, in train_step\n        y_pred = self(x, training=True)\n    File \"C:\\Users\\Juliu\\anaconda3\\lib\\site-packages\\keras\\utils\\traceback_utils.py\", line 70, in error_handler\n        raise e.with_traceback(filtered_tb) from None\n    File \"C:\\Users\\Juliu\\anaconda3\\lib\\site-packages\\keras\\engine\\input_spec.py\", line 295, in assert_input_compatibility\n        raise ValueError(\n\n    ValueError: Input 0 of layer \"sequential\" is incompatible with the layer: expected shape=(None, 15, 1), found shape=(None, 160)\n\n"}